Workbook

Sheet ISIAN DATA
B2: NOMOR REGISTER | F2: : | G2: 400.12.3.2/007/ VII/ 2026 | P2: =HYPERLINK("#'N1 LAKI-LAKI'!A1", "⬅️ N LAKI-LAKI") -> ⬅️ N LAKI-LAKI
B3: TANGGAL SURAT | F3: : | G3: TAMBI | H3: , TAMBI, 29 JULI 2026 | P3: =HYPERLINK("#'N1 PEREMPUAN'!A1", "⬅️ N1 PEREMPUAN") -> ⬅️ N1 PEREMPUAN
B4: TANGGAL PELAKSANAAN | F4: : | G4: 2026-09-23 | I4: Rabu | K4: EMAIL CATIN | P4: =HYPERLINK("#'N1 LAKI-LAKI'!A1", "⬅️ N1 LAKI-LAKI") -> ⬅️ N1 LAKI-LAKI
B5: JAM | F5: : | G5: JAM. 08.00 | P5: =HYPERLINK("#'N2 PEREMPUAN'!A1", "⬅️ N2 PEREMPUAN") -> ⬅️ N2 PEREMPUAN
B6: TEMPAT AKAD NIKAH | F6: : | G6: DI RUMAH MEMPELAI PUTRI RT 010 RW 002 DESA TAMBI WATUKUMPUL PEMALANG | P6: =HYPERLINK("#'N2 LAKI-LAKI'!A1", "⬅️ N2 LAKI-LAKI") -> ⬅️ N2 LAKI-LAKI
P7: =HYPERLINK("#'N4 PEREMPUAN'!A1", "⬅️ N4 PEREMPUAN") -> ⬅️ N4 PEREMPUAN
A8: 1 | B8: NAMA CALON PENGANTIN LAKI-LAKI | F8: : | G8: SAEFULOH | P8: =HYPERLINK("#'N4 LAKI-LAKI'!A1", "⬅️ N4 LAKI-LAKI") -> ⬅️ N4 LAKI-LAKI
A9: 2 | B9: BIN | F9: : | G9: KUNENI | P9: =HYPERLINK("#'N5 LAKI-LAKI'!A1", "⬅️ N5 LAKI-LAKI") -> ⬅️ N5 LAKI-LAKI
A10: 3 | B10: TEMPAT TANGGAL LAHIR | F10: : | G10: PURBALINGGA , 07 APRIL 2000 | J10: UMUR | K10: 26 | P10: =HYPERLINK("#'N5 PEREMPUAN'!A1", "⬅️ N5 PEREMPUAN") -> ⬅️ N5 PEREMPUAN
A11: 4 | B11: NIK | F11: : | G11: 3303170704000001 | P11: =HYPERLINK("#'N6 LAKI-LAKI'!A1", "⬅️ N6 LKI-LAKI") -> ⬅️ N6 LKI-LAKI
A12: 5 | B12: PEKERJAAN | F12: : | G12: KARYAWAN SWASTA | P12: =HYPERLINK("#'RDS'!A1", "⬅️ MENUJU RDS") -> ⬅️ MENUJU RDS
A13: 6 | B13: SETATUS | F13: : | G13: BELUM KAWIN | P13: =HYPERLINK("#'KENDALI PELAKSANAAN IJAB'!A1", "⬅️ KENDAI PEL IJAB") -> ⬅️ KENDAI PEL IJAB
A14: 7 | B14: JENIS KELAMIN | F14: : | G14: Laki-Laki | P14: =HYPERLINK("#'PERNYATAAN WALI HAKIM'!A1", "⬅️ WALI HAKIM") -> ⬅️ WALI HAKIM
A15: 8 | B15: NAMA ISTRI TERDAHULU | F15: : | P15: =HYPERLINK("#'SURAT KETERANGAN WALI'!A1", "⬅️ SUKET WALI") -> ⬅️ SUKET WALI
A16: 9 | B16: ALAMAT | F16: : | G16: RT 004 RW 001 DESA JINGKANG KECAMATAN KARANGJAMBU KABUPATEN PURBALINGGA | P16: =HYPERLINK("#'DISPENSASI'!A1", "⬅️ DISPENSASI") -> ⬅️ DISPENSASI
A17: 10 | B17: PENDIDIKAN | F17: : | G17: SLTA | P17: =HYPERLINK("#'STATUS CATIN PR'!A1", "⬅️ STATUS CATIN PR") -> ⬅️ STATUS CATIN PR
P18: =HYPERLINK("#'STATUS LAKI-LAKI'!A1", "⬅️ STATUS LAKI-LAKI") -> ⬅️ STATUS LAKI-LAKI
A19: 1 | B19: NAMA AYAH LAKI-LAKI | F19: : | G19: KUNENI | I19: bin | J19: SANBISRI
A20: 2 | B20: NIK | F20: : | G20: 3303170406740001
A21: 3 | B21: TEMPAT TANGGAL LAHIR | F21: : | G21: PURBALINGGA, 04 JUNI 1974 | J21: UMUR | K21: 52
A22: 4 | B22: PEKERJAAN | F22: : | G22: PETANI/ PEKEBUN
A23: 5 | B23: ALAMAT | F23: : | G23: RT 004 RW 001 DESA JINGKANG KECAMATAN KARANGJAMBU KABUPATEN PURBALINGGA
A26: 1 | B26: NAMA IBU LAKI-LAKI | G26: DARYATI | H26: BIN | I26: SUMIARTO
A27: 2 | B27: NIK | G27: 3303174705800003
A28: 3 | B28: TEMPAT TANGGAL LAHIR | G28: PURBALINGGA, 07 JUNI 1980 | J28: UMUR | K28: 46
A29: 4 | B29: PEKERJAAN | G29: Mengurus Rumah Tangga
A30: 5 | B30: ALAMAT | G30: RT 004 RW 001 DESA JINGKANG KECAMATAN KARANGJAMBU KABUPATEN PURBALINGGA
A34: 1 | B34: NAMA CALON PENGANTIN PEREMPUAN | F34: : | G34: SUSILAH
A35: 2 | B35: BINTI | F35: : | G35: RUSMAN
A36: 3 | B36: TEMPAT TANGGAL LAHIR | F36: : | G36: PEMALANG, 11 SEPTEMBER 1999 | J36: UMUR | K36: 27
A37: 4 | B37: NIK | F37: : | G37: 3327045109990007
A38: 5 | B38: PEKERJAAN | F38: : | G38: BELUM/ TIDAK BEKERJA
A39: 6 | B39: SETATUS | F39: : | G39: BELUM KAWIN
A40: 7 | B40: JENIS KELAMIN | F40: : | G40: PEREMPUAN
A41: 8 | B41: ALAMAT | F41: : | G41: RT 002 RW 004 DESA TAMBI KECAMATAN WATUKUMPUL KABUPATEN PEMALANG
A42: 9 | B42: NAMA SUAMI TERDHULU | F42: :
A43: 10 | B43: PENDIDIKAN | F43: : | G43: SLTA
A45: 1 | B45: NAMA AYAH PEREMPUAN | F45: : | G45: RUSMAN | H45: BIN | I45: MARTA
A46: 2 | B46: NIK | F46: : | G46: 3327040107740063
A47: 3 | B47: TEMPAT TANGGAL LAHIR | F47: : | G47: PEMALANG, 01 JULI 1974 | J47: UMUR | K47: 52
...

Sheet N1 PEREMPUAN
A4: PEMERINTAH KABUPATEN PEMALANG
A5: KECAMATAN WATUKUMPUL | M5: =HYPERLINK("#'Isian Data'!A1", "⬅️ Kembali ke Isisan Data") -> ⬅️ Kembali ke Isisan Data
A6: DESA | G6: ='ISIAN DATA'!G3 -> TAMBI
K7: Model N1
A8: PENGANTAR NIKAH
A9: Nomor . | F9: ='ISIAN DATA'!G2 -> 400.12.3.2/007/ VII/ 2026
A11: Yang bertanda tangan di bawah ini menjelaskan dengan sesungguhnya bahwa:
A12: 1 | B12: Nama | F12: : | G12: ='ISIAN DATA'!G34 -> SUSILAH
A13: 2 | B13: Nomor Induk Kependudukan (NIK) | F13: : | G13: ='ISIAN DATA'!G37 -> 3327045109990007
A14: 3 | B14: Jenis Kelamin | F14: : | G14: ='ISIAN DATA'!G40 -> PEREMPUAN
A15: 4 | B15: Tempat dan tanggal lahir | F15: : | G15: ='ISIAN DATA'!G36 -> PEMALANG, 11 SEPTEMBER 1999
A16: 5 | B16: Kewarganegaraan | F16: : | G16: INDONESIA
A17: 6 | B17: Agama | F17: : | G17: ISLAM
A18: 7 | B18: Pekerjaan | F18: : | G18: ='ISIAN DATA'!G12 -> KARYAWAN SWASTA
A19: 8 | B19: Alamat | F19: : | G19: ='ISIAN DATA'!G41 -> RT 002 RW 004 DESA TAMBI KECAMATAN WATUKUMPUL KABUPATEN PEMALANG
A21: 9 | C21: Status pernikahan
B22: a. | C22: Laki-laki; Jejaka, Duda | F22: : | G22: ='ISIAN DATA'!G39 -> BELUM KAWIN
C23: atau beristri ke ….... | F23: : | G23: …............................................................................
B24: b. | C24: Peremuan: Perawan, Janda
A26: Adalah benar-benar anak dari pernikahan seorang pria:
A27: Nama lengkap dan alias | F27: : | G27: ='ISIAN DATA'!G45 -> RUSMAN
A28: Nomor Induk Kependudukan (NIK) | F28: : | G28: ='ISIAN DATA'!G46 -> 3327040107740063
A29: Tempat dan tanggal lahir | F29: : | G29: ='ISIAN DATA'!G47 -> PEMALANG, 01 JULI 1974
A30: Kewarganegaraan | F30: : | G30: =G16 -> INDONESIA
A31: Agama | F31: : | G31: =G17 -> ISLAM
A32: Pekerjaan | F32: : | G32: ='ISIAN DATA'!G48 -> PETANI/ PEKEBUN
A33: Alamat | F33: : | G33: ='ISIAN DATA'!G49 -> RT 002 RW 004 DESA TAMBI KECAMATAN WATUKUMPUL KABUPATEN PEMALANG
A35: Dengan seorang wanita :
A36: Nama lengkap dan alias | F36: : | G36: ='ISIAN DATA'!G52 -> KHOSINGAH
A37: Nomor Induk Kependudukan (NIK) | F37: : | G37: ='ISIAN DATA'!G53 -> 3327044107810112
A38: Tempat dan tanggal lahir | F38: : | G38: ='ISIAN DATA'!G54 -> PEMALANG 01 JULI 1981
A39: Kewarganegaraan | F39: : | G39: INDONESIA
A40: Agama | F40: : | G40: ISLAM
A41: Pekerjaan | F41: : | G41: ='ISIAN DATA'!G55 -> Mengurus Rumah Tangga
A42: Alamat | F42: : | G42: ='ISIAN DATA'!G41 -> RT 002 RW 004 DESA TAMBI KECAMATAN WATUKUMPUL KABUPATEN PEMALANG
A44: Demikian surat pengantar ini dibuat dengan mengingat sumpah jabatan dan untuk
A45: dipergunakan sebagaimana mestinya
G47: ='ISIAN DATA'!G3 -> TAMBI | I47: ='ISIAN DATA'!H3 -> , TAMBI, 29 JULI 2026
G48: Kepala Desa Tambi
G52: J U R I

Sheet N1 LAKI-LAKI
A4: PEMERINTAH KABUPATEN PEMALANG
A5: KECAMATAN WATUKUMPUL | M5: =HYPERLINK("#'Isian Data'!A1", "⬅️ Kembali ke Isisan Data") -> ⬅️ Kembali ke Isisan Data
A6: DESA | G6: ='ISIAN DATA'!G3 -> TAMBI
K7: Model N1
A8: PENGANTAR NIKAH
A9: Nomor . | F9: ='ISIAN DATA'!G2 -> 400.12.3.2/007/ VII/ 2026
A11: Yang bertanda tangan di bawah ini menjelaskan dengan sesungguhnya bahwa:
A12: 1 | B12: Nama | F12: : | G12: ='ISIAN DATA'!G8 -> SAEFULOH
A13: 2 | B13: Nomor Induk Kependudukan (NIK) | F13: : | G13: ='ISIAN DATA'!G11 -> 3303170704000001
A14: 3 | B14: Jenis Kelamin | F14: : | G14: ='ISIAN DATA'!G14 -> Laki-Laki
A15: 4 | B15: Tempat dan tanggal lahir | F15: : | G15: ='ISIAN DATA'!G10 -> PURBALINGGA , 07 APRIL 2000
A16: 5 | B16: Kewarganegaraan | F16: : | G16: INDONESIA
A17: 6 | B17: Agama | F17: : | G17: ISLAM
A18: 7 | B18: Pekerjaan | F18: : | G18: ='ISIAN DATA'!G12 -> KARYAWAN SWASTA
A19: 8 | B19: Alamat | F19: : | G19: ='ISIAN DATA'!G16 -> RT 004 RW 001 DESA JINGKANG KECAMATAN KARANGJAMBU KABUPATEN PURBALINGGA
A21: 9 | C21: Status pernikahan
B22: a. | C22: Laki-laki; Jejaka, Duda | F22: : | G22: ='ISIAN DATA'!G13 -> BELUM KAWIN
C23: atau beristri ke ….... | F23: : | G23: …............................................................................
B24: b. | C24: Peremuan: Perawan, Janda
A26: Adalah benar-benar anak dari pernikahan seorang pria:
A27: Nama lengkap dan alias | F27: : | G27: ='ISIAN DATA'!G19 -> KUNENI
A28: Nomor Induk Kependudukan (NIK) | F28: : | G28: ='ISIAN DATA'!G20 -> 3303170406740001
A29: Tempat dan tanggal lahir | F29: : | G29: ='ISIAN DATA'!G21 -> PURBALINGGA, 04 JUNI 1974
A30: Kewarganegaraan | F30: : | G30: =G16 -> INDONESIA
A31: Agama | F31: : | G31: =G17 -> ISLAM
A32: Pekerjaan | F32: : | G32: ='ISIAN DATA'!G22 -> PETANI/ PEKEBUN
A33: Alamat | F33: : | G33: ='ISIAN DATA'!G23 -> RT 004 RW 001 DESA JINGKANG KECAMATAN KARANGJAMBU KABUPATEN PURBALINGGA
A35: Dengan seorang wanita :
A36: Nama lengkap dan alias | F36: : | G36: ='ISIAN DATA'!G26 -> DARYATI
A37: Nomor Induk Kependudukan (NIK) | F37: : | G37: ='ISIAN DATA'!G27 -> 3303174705800003
A38: Tempat dan tanggal lahir | F38: : | G38: ='ISIAN DATA'!G28 -> PURBALINGGA, 07 JUNI 1980
A39: Kewarganegaraan | F39: : | G39: INDONESIA
A40: Agama | F40: : | G40: ISLAM
A41: Pekerjaan | F41: : | G41: ='ISIAN DATA'!G22 -> PETANI/ PEKEBUN
A42: Alamat | F42: : | G42: ='ISIAN DATA'!G30 -> RT 004 RW 001 DESA JINGKANG KECAMATAN KARANGJAMBU KABUPATEN PURBALINGGA
A44: Demikian surat pengantar ini dibuat dengan mengingat sumpah jabatan dan untuk
A45: dipergunakan sebagaimana mestinya
G47: ='ISIAN DATA'!G3 -> TAMBI | I47: ='ISIAN DATA'!H3 -> , TAMBI, 29 JULI 2026
G48: Kepala Desa Tambi
G52: J U R I

Sheet N2 PEREMPUAN
A1: Penyesuaian Lampiran VI | N1: =HYPERLINK("#'Isian Data'!A1", "⬅️ Kembali ke Isisan Data") -> ⬅️ Kembali ke Isisan Data
A2: Keputusan Dirjen Bimas Islam Nomor 473 Tahun 2020
A4: Perihal | C4: : | D4: Permohonan Kehendak Pernikahan
A6: Kepada Yth.
A7: Kepala KUA Watukumpul
A8: di tempat
A10: Assalamu'alaikum Warahmatullahi Wabarakatuh
A11: Dengan hormat, kami mengajukan permohonan kehendak pernikahan untuk atas nama:
A12: Calon suami | F12: : | G12: ='ISIAN DATA'!G8 -> SAEFULOH
A13: Calon istri | F13: : | G13: ='ISIAN DATA'!G34 -> SUSILAH
A14: Pada hari | F14: : | G14: ='ISIAN DATA'!I4 -> Rabu | I14: ='ISIAN DATA'!G4 -> 2026-09-23
A15: Bertempat di | F15: : | G15: ='ISIAN DATA'!G41 -> RT 002 RW 004 DESA TAMBI KECAMATAN WATUKUMPUL KABUPATEN PEMALANG
A17: Bersama ini kami sampaikan surat-surat yang diperlukan untuk diperiksa sebagai berikut :
A18: A. Berkas Utama :
A19: 1 | C19: Surat pengantar pernikahan dari Desa/ Kelurahan calon pengantin Putra
A20: 2 | C20: (Diurutkan dari N1, N5, AC Asli, Berkas Khusus TNI/ Polri dari Rekomendasi)
A21: 3 | C21: Surat Pengantar Pernikahan dari Desa/ Kelurahan Calon Pengantin Putri
A22: 4 | C22: (Diurutkan dari N1, N5, AC Asli, Berkas Khusus TNI/Polri dan Rekomendasi)
A23: 5 | C23: Surat Persetujuan Mempelai (Model N4)
A24: 6 | C24: Asli Putusan Dispensasi Umur dari Pengadilan Agama
A25: 7 | C25: Pasfoto ukuran 2x3 = 2 lembar dan 4x6= 1 lembar berlatar belakang biru
A27: B. Berkas Operator
A28: 1 | C28: Rekam Data Sementara Calon Pengantin
A29: 2 | C29: Surat Keterangan Wali dan Pernyataannya
A30: 3 | C30: Fotocopy Akte Kelahiran dan Ijazah
A31: 4 | C31: Fotocopy KTP, Catin Putra, Catin Putri, Wali
A32: 5 | C32: Fotocopy Kartu Keluarga Catin Putra, Catin Putri, Wali
A34: Demikian permohonan ini kami sampaikan, kiranya dapat diperiksa, dihadiri dan dicatat
A35: sesuai dengan ketentuan peraturan perundang-undangan.
A37: Wassalamualaikum Warahmatullahi Wabarakatuh
A39: Diterima tanggal ……………..……… 2026
A40: Yang menerima,
A41: Kepala KUA/ Penghulu | K41: Pemohon
A45: ….............................. | K45: =G13 -> SUSILAH
K49: Petugas Pengantar,
K53: Chalim Muchtarom, S.Pd.I

Sheet N2 LAKI-LAKI
A1: Penyesuaian Lampiran VI | N1: =HYPERLINK("#'Isian Data'!A1", "⬅️ Kembali ke Isisan Data") -> ⬅️ Kembali ke Isisan Data
A2: Keputusan Dirjen Bimas Islam Nomor 473 Tahun 2020
A4: Perihal | C4: : | D4: Permohonan Kehendak Pernikahan
A6: Kepada Yth.
A7: Kepala KUA Watukumpul
A8: di tempat
A10: Assalamu'alaikum Warahmatullahi Wabarakatuh
A11: Dengan hormat, kami mengajukan permohonan kehendak pernikahan untuk atas nama:
A12: Calon suami | F12: : | G12: ='ISIAN DATA'!G8 -> SAEFULOH
A13: Calon istri | F13: : | G13: ='ISIAN DATA'!G34 -> SUSILAH
A14: Pada hari | F14: : | G14: ='N2 PEREMPUAN'!G14:H14 -> Rabu | I14: ='N2 PEREMPUAN'!I14:J14 -> 2026-09-23
A15: Bertempat di | F15: : | G15: ='ISIAN DATA'!G41 -> RT 002 RW 004 DESA TAMBI KECAMATAN WATUKUMPUL KABUPATEN PEMALANG
A17: Bersama ini kami sampaikan surat-surat yang diperlukan untuk diperiksa sebagai berikut :
A18: A. Berkas Utama :
A19: 1 | C19: Surat pengantar pernikahan dari Desa/ Kelurahan calon pengantin Putra
A20: 2 | C20: (Diurutkan dari N1, N5, AC Asli, Berkas Khusus TNI/ Polri dari Rekomendasi)
A21: 3 | C21: Surat Pengantar Pernikahan dari Desa/ Kelurahan Calon Pengantin Putri
A22: 4 | C22: (Diurutkan dari N1, N5, AC Asli, Berkas Khusus TNI/Polri dan Rekomendasi)
A23: 5 | C23: Surat Persetujuan Mempelai (Model N4)
A24: 6 | C24: Asli Putusan Dispensasi Umur dari Pengadilan Agama
A25: 7 | C25: Pasfoto ukuran 2x3 = 2 lembar dan 4x6= 1 lembar berlatar belakang biru
A27: B. Berkas Operator
A28: 1 | C28: Rekam Data Sementara Calon Pengantin
A29: 2 | C29: Surat Keterangan Wali dan Pernyataannya
A30: 3 | C30: Fotocopy Akte Kelahiran dan Ijazah
A31: 4 | C31: Fotocopy KTP, Catin Putra, Catin Putri, Wali
A32: 5 | C32: Fotocopy Kartu Keluarga Catin Putra, Catin Putri, Wali
A34: Demikian permohonan ini kami sampaikan, kiranya dapat diperiksa, dihadiri dan dicatat
A35: sesuai dengan ketentuan peraturan perundang-undangan.
A37: Wassalamualaikum Warahmatullahi Wabarakatuh
A39: Diterima tanggal ……………..……… 2026
A40: Yang menerima,
A41: Kepala KUA/ Penghulu | K41: Pemohon
A45: ….............................. | K45: ='N1 LAKI-LAKI'!G12 -> SAEFULOH
K49: Petugas Pengantar,
K53: Chalim Muchtarom, S.Pd.I

Sheet N4 PEREMPUAN
A1: Penyesuaian Lampiran VIII | M1: =HYPERLINK("#'Isian Data'!A1", "⬅️ Kembali ke Isisan Data") -> ⬅️ Kembali ke Isisan Data
A2: Keputusan Dirjen Bimas Islam Nomor 473 Tahun 2020
A3: Model N4
A5: PERSETUJUAN CALON PENGANTIN
A7: Yang bertanda tangan di bawah ini :
A8: A. | B8: Calon Suami:
B9: 1 | D9: Nama lengkap dan alias | G9: : | H9: ='ISIAN DATA'!G8 -> SAEFULOH
B10: 2 | D10: Bin | G10: : | H10: ='ISIAN DATA'!G9 -> KUNENI
B11: 3 | D11: Nomor Induk Kependudukan | G11: : | H11: ='ISIAN DATA'!G11 -> 3303170704000001
B12: 4 | D12: Tempat dan tanggal lahir | G12: : | H12: ='ISIAN DATA'!G10 -> PURBALINGGA , 07 APRIL 2000
B13: 5 | D13: Kewarganegaraan | G13: : | H13: ='N1 LAKI-LAKI'!G30 -> INDONESIA
B14: 6 | D14: Agama | G14: : | H14: ='N1 LAKI-LAKI'!G31 -> ISLAM
B15: 7 | D15: Pekerjaan | G15: : | H15: ='ISIAN DATA'!G12 -> KARYAWAN SWASTA
B16: 8 | D16: Alamat | G16: : | H16: ='ISIAN DATA'!G16 -> RT 004 RW 001 DESA JINGKANG KECAMATAN KARANGJAMBU KABUPATEN PURBALINGGA
A19: B. | B19: Calon Istri:
B20: 1 | D20: Nama lengkap dan alias | G20: : | H20: ='ISIAN DATA'!G34 -> SUSILAH
B21: 2 | D21: Binti | G21: : | H21: ='ISIAN DATA'!G35 -> RUSMAN
B22: 3 | D22: Nomor Induk Kependudukan | G22: : | H22: ='ISIAN DATA'!G37 -> 3327045109990007
B23: 4 | D23: Tempat dan tanggal lahir | G23: : | H23: ='ISIAN DATA'!G36 -> PEMALANG, 11 SEPTEMBER 1999
B24: 5 | D24: Kewarganegaraan | G24: : | H24: ='N1 LAKI-LAKI'!G39 -> INDONESIA
B25: 6 | D25: Agama | G25: : | H25: ='N1 LAKI-LAKI'!G40 -> ISLAM
B26: 7 | D26: Pekerjaan | G26: : | H26: ='ISIAN DATA'!G38 -> BELUM/ TIDAK BEKERJA
B27: 8 | D27: Alamat | G27: : | H27: ='ISIAN DATA'!G41 -> RT 002 RW 004 DESA TAMBI KECAMATAN WATUKUMPUL KABUPATEN PEMALANG
A30: Menyatakan dengan sesungguhnya bahwa atas dasar suka rela, dengan kesadaran sendiri, tanpa
A31: ada paksaan dari siapapun juga, setuju untuk melangsungkan pernikahan.
A33: Demikian surat persetujuan ini dibuat untuk digunakan seperlunya.
I36: ='N1 LAKI-LAKI'!G47 -> TAMBI | J36: ='N1 LAKI-LAKI'!I47 -> , TAMBI, 29 JULI 2026
A38: Calon Suami | I38: Calon Istri
A41: =H9 -> SAEFULOH | I41: =H20 -> SUSILAH

Sheet N4 LAKI-LAKI
A1: Penyesuaian Lampiran VIII | M1: =HYPERLINK("#'Isian Data'!A1", "⬅️ Kembali ke Isisan Data") -> ⬅️ Kembali ke Isisan Data
A2: Keputusan Dirjen Bimas Islam Nomor 473 Tahun 2020
A3: Model N4
A5: PERSETUJUAN CALON PENGANTIN
A7: Yang bertanda tangan di bawah ini :
A8: A. | B8: Calon Suami:
B9: 1 | D9: Nama lengkap dan alias | G9: : | H9: ='ISIAN DATA'!G8 -> SAEFULOH
B10: 2 | D10: Bin | G10: : | H10: ='ISIAN DATA'!G9 -> KUNENI
B11: 3 | D11: Nomor Induk Kependudukan | G11: : | H11: ='ISIAN DATA'!G11 -> 3303170704000001
B12: 4 | D12: Tempat dan tanggal lahir | G12: : | H12: ='ISIAN DATA'!G10 -> PURBALINGGA , 07 APRIL 2000
B13: 5 | D13: Kewarganegaraan | G13: : | H13: ='N1 LAKI-LAKI'!G30 -> INDONESIA
B14: 6 | D14: Agama | G14: : | H14: ='N1 LAKI-LAKI'!G31 -> ISLAM
B15: 7 | D15: Pekerjaan | G15: : | H15: ='ISIAN DATA'!G12 -> KARYAWAN SWASTA
B16: 8 | D16: Alamat | G16: : | H16: ='ISIAN DATA'!G16 -> RT 004 RW 001 DESA JINGKANG KECAMATAN KARANGJAMBU KABUPATEN PURBALINGGA
A19: B. | B19: Calon Istri:
B20: 1 | D20: Nama lengkap dan alias | G20: : | H20: ='ISIAN DATA'!G34 -> SUSILAH
B21: 2 | D21: Binti | G21: : | H21: ='ISIAN DATA'!G35 -> RUSMAN
B22: 3 | D22: Nomor Induk Kependudukan | G22: : | H22: ='ISIAN DATA'!G37 -> 3327045109990007
B23: 4 | D23: Tempat dan tanggal lahir | G23: : | H23: ='ISIAN DATA'!G36 -> PEMALANG, 11 SEPTEMBER 1999
B24: 5 | D24: Kewarganegaraan | G24: : | H24: ='N1 LAKI-LAKI'!G39 -> INDONESIA
B25: 6 | D25: Agama | G25: : | H25: ='N1 LAKI-LAKI'!G40 -> ISLAM
B26: 7 | D26: Pekerjaan | G26: : | H26: ='ISIAN DATA'!G38 -> BELUM/ TIDAK BEKERJA
B27: 8 | D27: Alamat | G27: : | H27: ='ISIAN DATA'!G41 -> RT 002 RW 004 DESA TAMBI KECAMATAN WATUKUMPUL KABUPATEN PEMALANG
A30: Menyatakan dengan sesungguhnya bahwa atas dasar suka rela, dengan kesadaran sendiri, tanpa
A31: ada paksaan dari siapapun juga, setuju untuk melangsungkan pernikahan.
A33: Demikian surat persetujuan ini dibuat untuk digunakan seperlunya.
I36: ='N1 LAKI-LAKI'!G47 -> TAMBI | J36: ='N1 LAKI-LAKI'!I47 -> , TAMBI, 29 JULI 2026
A38: Calon Suami | I38: Calon Istri
A41: =H9 -> SAEFULOH | I41: =H20 -> SUSILAH

Sheet N5 LAKI-LAKI
A1: Penyesuaian Lampiran IX | L1: =HYPERLINK("#'Isian Data'!A1", "⬅️ Kembali ke Isisan Data") -> ⬅️ Kembali ke Isisan Data
A2: Keputusan Dirjen Bimas Islam Nomor 473 Tahun 2020
A4: Model N5
A5: SURAT IZIN ORANG TUA/ PENGAMPU
B7: Yang bertanda tangan di bawah ini :
A9: A. | B9: 1 | C9: Nama lengkap dan alias | F9: : | G9: ='ISIAN DATA'!G19 -> KUNENI
B10: 2 | C10: Bin | F10: : | G10: ='ISIAN DATA'!J19 -> SANBISRI
B11: 3 | C11: Nomor Induk Kependudukan | F11: : | G11: ='ISIAN DATA'!G20 -> 3303170406740001
B12: 4 | C12: Tempat dan tanggal lahir | F12: : | G12: ='ISIAN DATA'!G21 -> PURBALINGGA, 04 JUNI 1974
B13: 5 | C13: Kewarganegaraan | F13: : | G13: ='N1 LAKI-LAKI'!G39 -> INDONESIA
B14: 6 | C14: Agama | F14: : | G14: ='N1 LAKI-LAKI'!G40 -> ISLAM
B15: 7 | C15: Pekerjaan | F15: : | G15: ='ISIAN DATA'!G22 -> PETANI/ PEKEBUN
B16: 8 | C16: Alamat | F16: : | G16: ='ISIAN DATA'!G23 -> RT 004 RW 001 DESA JINGKANG KECAMATAN KARANGJAMBU KABUPATEN PURBALINGGA
A20: B. | B20: 1 | C20: Nama lengkap dan alias | F20: : | G20: ='ISIAN DATA'!G26 -> DARYATI
B21: 2 | C21: Binti | F21: : | G21: ='ISIAN DATA'!I26 -> SUMIARTO
B22: 3 | C22: Nomor Induk Kependudukan | F22: : | G22: ='ISIAN DATA'!G27 -> 3303174705800003
B23: 4 | C23: Tempat dan tanggal lahir | F23: : | G23: ='ISIAN DATA'!G28 -> PURBALINGGA, 07 JUNI 1980
B24: 5 | C24: Kewarganegaraan | F24: : | G24: ='N1 LAKI-LAKI'!G39 -> INDONESIA
B25: 6 | C25: Agama | F25: : | G25: ='N1 LAKI-LAKI'!G40 -> ISLAM
B26: 7 | C26: Pekerjaan | F26: : | G26: ='ISIAN DATA'!G29 -> Mengurus Rumah Tangga
B27: 8 | C27: Alamat | F27: : | G27: ='ISIAN DATA'!G30 -> RT 004 RW 001 DESA JINGKANG KECAMATAN KARANGJAMBU KABUPATEN PURBALINGGA
G28: …........................................................................
B29: adalah ayah dan ibu kandung/ wali/ pengampu dari :
B30: 1 | C30: Nama lengkap dan alias | F30: : | G30: ='ISIAN DATA'!G8 -> SAEFULOH
B31: 2 | C31: Bin/ Binti | F31: : | G31: =G9 -> KUNENI
B32: 3 | C32: Nomor Induk Kependudukan | F32: : | G32: ='N4 PEREMPUAN'!H11 -> 3303170704000001
B33: 4 | C33: Tempat dan tanggal lahir | F33: : | G33: ='ISIAN DATA'!G10 -> PURBALINGGA , 07 APRIL 2000
B34: 5 | C34: Kewarganegaraan | F34: : | G34: ='N4 PEREMPUAN'!H13 -> INDONESIA
B35: 6 | C35: Agama | F35: : | G35: ='N4 PEREMPUAN'!H14 -> ISLAM
B36: 7 | C36: Pekerjaan | F36: : | G36: ='ISIAN DATA'!G12 -> KARYAWAN SWASTA
B37: 8 | C37: Alamat | F37: : | G37: ='ISIAN DATA'!G16 -> RT 004 RW 001 DESA JINGKANG KECAMATAN KARANGJAMBU KABUPATEN PURBALINGGA
G38: …........................................................................
B39: memberikan izin kepada yang bersangkutan untuk melakukan pernikahan dengan :
B40: 1 | C40: Nama lengkap dan alias | F40: : | G40: ='ISIAN DATA'!G34 -> SUSILAH
B41: 2 | C41: Bin/ Binti | F41: : | G41: ='ISIAN DATA'!G45 -> RUSMAN
B42: 3 | C42: Nomor Induk Kependudukan | F42: : | G42: ='ISIAN DATA'!G37 -> 3327045109990007
B43: 4 | C43: Tempat dan tanggal lahir | F43: : | G43: ='ISIAN DATA'!G36 -> PEMALANG, 11 SEPTEMBER 1999
B44: 5 | C44: Kewarganegaraan | F44: : | G44: ='N4 PEREMPUAN'!H13 -> INDONESIA
B45: 6 | C45: Agama | F45: : | G45: ='N4 PEREMPUAN'!H14 -> ISLAM
B46: 7 | C46: Pekerjaan | F46: : | G46: ='ISIAN DATA'!G38 -> BELUM/ TIDAK BEKERJA
...

Sheet N5 PEREMPUAN
A1: Penyesuaian Lampiran IX | L1: =HYPERLINK("#'Isian Data'!A1", "⬅️ Kembali ke Isisan Data") -> ⬅️ Kembali ke Isisan Data
A2: Keputusan Dirjen Bimas Islam Nomor 473 Tahun 2020
A4: Model N5
A5: SURAT IZIN ORANG TUA/ PENGAMPU
B7: Yang bertanda tangan di bawah ini :
A9: A. | B9: 1 | C9: Nama lengkap dan alias | F9: : | G9: ='ISIAN DATA'!G45 -> RUSMAN
B10: 2 | C10: Bin | F10: : | G10: ='ISIAN DATA'!I45 -> MARTA
B11: 3 | C11: Nomor Induk Kependudukan | F11: : | G11: ='ISIAN DATA'!G46 -> 3327040107740063
B12: 4 | C12: Tempat dan tanggal lahir | F12: : | G12: ='ISIAN DATA'!G47 -> PEMALANG, 01 JULI 1974
B13: 5 | C13: Kewarganegaraan | F13: : | G13: ='N1 LAKI-LAKI'!G39 -> INDONESIA
B14: 6 | C14: Agama | F14: : | G14: ='N1 LAKI-LAKI'!G40 -> ISLAM
B15: 7 | C15: Pekerjaan | F15: : | G15: ='ISIAN DATA'!G48 -> PETANI/ PEKEBUN
B16: 8 | C16: Alamat | F16: : | G16: ='ISIAN DATA'!G49 -> RT 002 RW 004 DESA TAMBI KECAMATAN WATUKUMPUL KABUPATEN PEMALANG
A20: B. | B20: 1 | C20: Nama lengkap dan alias | F20: : | G20: ='ISIAN DATA'!G52 -> KHOSINGAH
B21: 2 | C21: Binti | F21: : | G21: ='ISIAN DATA'!I52 -> NASIR
B22: 3 | C22: Nomor Induk Kependudukan | F22: : | G22: ='ISIAN DATA'!G53 -> 3327044107810112
B23: 4 | C23: Tempat dan tanggal lahir | F23: : | G23: ='ISIAN DATA'!G54 -> PEMALANG 01 JULI 1981
B24: 5 | C24: Kewarganegaraan | F24: : | G24: ='N1 LAKI-LAKI'!G39 -> INDONESIA
B25: 6 | C25: Agama | F25: : | G25: ='N1 LAKI-LAKI'!G40 -> ISLAM
B26: 7 | C26: Pekerjaan | F26: : | G26: ='ISIAN DATA'!G55 -> Mengurus Rumah Tangga
B27: 8 | C27: Alamat | F27: : | G27: ='ISIAN DATA'!G56 -> RT 002 RW 004 DESA TAMBI KECAMATAN WATUKUMPUL KABUPATEN PEMALANG
G28: …........................................................................
B29: adalah ayah dan ibu kandung/ wali/ pengampu dari :
B30: 1 | C30: Nama lengkap dan alias | F30: : | G30: ='N5 LAKI-LAKI'!G40 -> SUSILAH
B31: 2 | C31: Bin/ Binti | F31: : | G31: ='N5 LAKI-LAKI'!G41 -> RUSMAN
B32: 3 | C32: Nomor Induk Kependudukan | F32: : | G32: ='N5 LAKI-LAKI'!G42 -> 3327045109990007
B33: 4 | C33: Tempat dan tanggal lahir | F33: : | G33: ='N5 LAKI-LAKI'!G43 -> PEMALANG, 11 SEPTEMBER 1999
B34: 5 | C34: Kewarganegaraan | F34: : | G34: ='N5 LAKI-LAKI'!G44 -> INDONESIA
B35: 6 | C35: Agama | F35: : | G35: ='N5 LAKI-LAKI'!G45 -> ISLAM
B36: 7 | C36: Pekerjaan | F36: : | G36: ='N5 LAKI-LAKI'!G46 -> BELUM/ TIDAK BEKERJA
B37: 8 | C37: Alamat | F37: : | G37: ='N5 LAKI-LAKI'!G47 -> RT 002 RW 004 DESA TAMBI KECAMATAN WATUKUMPUL KABUPATEN PEMALANG
B39: memberikan izin kepada yang bersangkutan untuk melakukan pernikahan dengan :
B40: 1 | C40: Nama lengkap dan alias | F40: : | G40: ='N5 LAKI-LAKI'!G30 -> SAEFULOH
B41: 2 | C41: Bin/ Binti | F41: : | G41: ='N5 LAKI-LAKI'!G31 -> KUNENI
B42: 3 | C42: Nomor Induk Kependudukan | F42: : | G42: ='N5 LAKI-LAKI'!G32 -> 3303170704000001
B43: 4 | C43: Tempat dan tanggal lahir | F43: : | G43: ='N5 LAKI-LAKI'!G33 -> PURBALINGGA , 07 APRIL 2000
B44: 5 | C44: Kewarganegaraan | F44: : | G44: ='N5 LAKI-LAKI'!G34 -> INDONESIA
B45: 6 | C45: Agama | F45: : | G45: ='N5 LAKI-LAKI'!G35 -> ISLAM
B46: 7 | C46: Pekerjaan | F46: : | G46: ='N5 LAKI-LAKI'!G36 -> KARYAWAN SWASTA
B47: 8 | C47: Alamat | F47: : | G47: ='N5 LAKI-LAKI'!G37 -> RT 004 RW 001 DESA JINGKANG KECAMATAN KARANGJAMBU KABUPATEN PURBALINGGA
...

Sheet N6 PEREMPUAN
M2: =HYPERLINK("#'Isian Data'!A1", "⬅️ Kembali ke Isisan Data") -> ⬅️ Kembali ke Isisan Data
A4: PEMERINTAH KABUPATEN PEMALANG
A5: KECAMATAN WATUKUMPUL
A6: DESA XXXXX
K7: Model N6
A8: SURAT KETERANGAN KEMATIAN SUAMI / ISTRI
A9: Nomor : 474.3/………/…….…/20..
A11: Yang bertandatangan di bawah ini menerangkan dengan sesungguhnya bahwa:
A12: A. | B12: 1 | C12: Nama lengkap dan alias | F12: : | G12: ….........................................................................
B13: 2 | C13: Bin/ Binti | F13: : | G13: ….........................................................................
B14: 3 | C14: Nomor Induk Kependudukan | F14: : | G14: ….........................................................................
B15: 4 | C15: Tempat dan tanggal lahir | F15: : | G15: ….........................................................................
B16: 5 | C16: Kewarganegaraan | F16: : | G16: ….........................................................................
B17: 6 | C17: Agama | F17: : | G17: ….........................................................................
B18: 7 | C18: Pekerjaan | F18: : | G18: ….........................................................................
B19: 8 | C19: Alamat | F19: : | G19: ….........................................................................
G20: ….........................................................................
B21: TELAH MENINGGAL DUNIA
C22: pada tanggal | F22: : | G22: ….........................................................................
C23: bertempat di | F23: : | G23: ….........................................................................
B25: Yang bersangkutan adalah suami/ istri* dari:
B26: 1 | C26: Nama lengkap dan alias | F26: : | G26: ….........................................................................
B27: 2 | C27: Bin/ Binti | F27: : | G27: ….........................................................................
B28: 3 | C28: Nomor Induk Kependudukan | F28: : | G28: ….........................................................................
B29: 4 | C29: Tempat dan tanggal lahir | F29: : | G29: ….........................................................................
B30: 5 | C30: Kewarganegaraan | F30: : | G30: ….........................................................................
B31: 6 | C31: Agama | F31: : | G31: ….........................................................................
B32: 7 | C32: Pekerjaan | F32: : | G32: ….........................................................................
B33: 8 | C33: Alamat | F33: : | G33: ….........................................................................
G34: ….........................................................................
B35: Demikian surat keterangan ini dibuat dengan mengingat sumpah jabatan dan untuk
A36: digunakan seperlunya.
H39: Watukumpul, ……….…….…….. 2026
H40: Kepala Desa,
H44: .........................................
A46: *) Coret yang tidak perlu

Sheet N6 LAKI-LAKI
A4: PEMERINTAH KABUPATEN PEMALANG | M4: =HYPERLINK("#'Isian Data'!A1", "⬅️ Kembali ke Isisan Data") -> ⬅️ Kembali ke Isisan Data
A5: KECAMATAN WATUKUMPUL
A6: DESA XXXXX
K7: Model N6
A8: SURAT KETERANGAN KEMATIAN SUAMI / ISTRI
A9: Nomor : 474.3/………/…….…/20..
A11: Yang bertandatangan di bawah ini menerangkan dengan sesungguhnya bahwa:
A12: A. | B12: 1 | C12: Nama lengkap dan alias | F12: : | G12: ….........................................................................
B13: 2 | C13: Bin/ Binti | F13: : | G13: ….........................................................................
B14: 3 | C14: Nomor Induk Kependudukan | F14: : | G14: ….........................................................................
B15: 4 | C15: Tempat dan tanggal lahir | F15: : | G15: ….........................................................................
B16: 5 | C16: Kewarganegaraan | F16: : | G16: ….........................................................................
B17: 6 | C17: Agama | F17: : | G17: ….........................................................................
B18: 7 | C18: Pekerjaan | F18: : | G18: ….........................................................................
B19: 8 | C19: Alamat | F19: : | G19: ….........................................................................
G20: ….........................................................................
B21: TELAH MENINGGAL DUNIA
C22: pada tanggal | F22: : | G22: ….........................................................................
C23: bertempat di | F23: : | G23: ….........................................................................
B25: Yang bersangkutan adalah suami/ istri* dari:
B26: 1 | C26: Nama lengkap dan alias | F26: : | G26: ….........................................................................
B27: 2 | C27: Bin/ Binti | F27: : | G27: ….........................................................................
B28: 3 | C28: Nomor Induk Kependudukan | F28: : | G28: ….........................................................................
B29: 4 | C29: Tempat dan tanggal lahir | F29: : | G29: ….........................................................................
B30: 5 | C30: Kewarganegaraan | F30: : | G30: ….........................................................................
B31: 6 | C31: Agama | F31: : | G31: ….........................................................................
B32: 7 | C32: Pekerjaan | F32: : | G32: ….........................................................................
B33: 8 | C33: Alamat | F33: : | G33: ….........................................................................
G34: ….........................................................................
B35: Demikian surat keterangan ini dibuat dengan mengingat sumpah jabatan dan untuk
A36: digunakan seperlunya.
H39: Watukumpul, ……….…….…….. 2026
H40: Kepala Desa,
H44: .........................................
A46: *) Coret yang tidak perlu

Sheet RDS
A1: REKAM DATA SEMENTARA | O1: =HYPERLINK("#'Isian Data'!A1", "⬅️ Kembali ke Isisan Data") -> ⬅️ Kembali ke Isisan Data
A2: PENDAFTARAN CALON PASANGAN PENGANTIN
A4: A. | C4: PELAKSANAAN
C5: Hari, Tanggal | F5: : | G5: ='ISIAN DATA'!G4 -> 2026-09-23 | K5: Jam : …........... WIB
C6: Lokasi Akad Nikah | F6: : | G6: ='ISIAN DATA'!G6 -> DI RUMAH MEMPELAI PUTRI RT 010 RW 002 DESA TAMBI WATUKUMPUL PEMALANG
C7: Alamat Email Catin | F7: : | G7: ='ISIAN DATA'!K5 -> 0
A9: B. | C9: CALON SUAMI
B10: 1. | C10: Nama lengkap | F10: : | G10: ='ISIAN DATA'!G8 -> SAEFULOH
C11: Tempat, tanggal lahir | F11: : | G11: ='ISIAN DATA'!G10 -> PURBALINGGA , 07 APRIL 2000 | J11: NIK : | K11: ='ISIAN DATA'!G11 -> 3303170704000001
C12: nomor HP | F12: : | J12: Pekerjaan : | K12: ='ISIAN DATA'!G17 -> SLTA
C13: Pekerjaan | F13: : | J13: Anak ke : | K13: 1
C14: Status | F14: : | G14: Jejaka / Duda cerai / Duda ditinggal Mati / Beristri (Coret yang tidak perlu)
C15: Tempat tinggal | F15: : | G15: ='ISIAN DATA'!G16 -> RT 004 RW 001 DESA JINGKANG KECAMATAN KARANGJAMBU KABUPATEN PURBALINGGA
C16: Nomor & tgl putusan | F16: : | J16: Tanggal :
B18: 2. | C18: Nama Ayah kandung | F18: : | G18: ='ISIAN DATA'!G19 -> KUNENI | J18: NIK : | K18: ='ISIAN DATA'!G20 -> 3303170406740001
C19: Tempat, tanggal lahir | F19: : | G19: ='ISIAN DATA'!G21 -> PURBALINGGA, 04 JUNI 1974 | J19: Pekerjaan : | K19: ='ISIAN DATA'!G22 -> PETANI/ PEKEBUN
C20: Tempat tinggal | F20: : | G20: ='ISIAN DATA'!G23 -> RT 004 RW 001 DESA JINGKANG KECAMATAN KARANGJAMBU KABUPATEN PURBALINGGA
G21: Status pernikahan orangtua (Jika keduanya masih hidup) : Bersama / Bercerai
B22: 3. | C22: Nama Ibu kandung | F22: : | G22: ='ISIAN DATA'!G26 -> DARYATI | J22: NIK : | K22: ='ISIAN DATA'!G27 -> 3303174705800003
C23: Tempat, tanggal lahir | F23: : | G23: ='ISIAN DATA'!G28 -> PURBALINGGA, 07 JUNI 1980 | J23: Pekerjaan : | K23: ='ISIAN DATA'!G29 -> Mengurus Rumah Tangga
C24: Tempat tinggal | F24: : | G24: ='ISIAN DATA'!G30 -> RT 004 RW 001 DESA JINGKANG KECAMATAN KARANGJAMBU KABUPATEN PURBALINGGA
A26: C. | C26: CALON ISTRI
B27: 1. | C27: Nama lengkap | F27: : | G27: ='ISIAN DATA'!G34 -> SUSILAH | J27: NIK : | K27: ='ISIAN DATA'!G37 -> 3327045109990007
C28: Tempat, tanggal lahir | F28: : | G28: ='ISIAN DATA'!G36 -> PEMALANG, 11 SEPTEMBER 1999 | J28: Pekerjaan : | K28: ='ISIAN DATA'!G43 -> SLTA
C29: nomor HP | F29: : | G29: 082326132987 | I29: Anak ke :
C30: Pekerjaan | F30: : | G30: Perawan / Janda cerai / Janda ditinggal mati (coret yang tidak perlu)
C31: Status | F31: : | G31: ='ISIAN DATA'!G39 -> BELUM KAWIN
C32: Tempat tinggal | F32: : | G32: ='ISIAN DATA'!G41 -> RT 002 RW 004 DESA TAMBI KECAMATAN WATUKUMPUL KABUPATEN PEMALANG
C33: Nomor & tgl putusan | F33: : | J33: Tanggal :
B35: 2. | C35: Nama Ayah kandung | F35: : | G35: ='ISIAN DATA'!G45 -> RUSMAN | J35: NIK : | K35: ='ISIAN DATA'!G46 -> 3327040107740063
C36: Tempat, tanggal lahir | F36: : | G36: ='ISIAN DATA'!G47 -> PEMALANG, 01 JULI 1974 | J36: Pekerjaan : | K36: ='ISIAN DATA'!G48 -> PETANI/ PEKEBUN
C37: Tempat tinggal | F37: : | G37: ='ISIAN DATA'!G49 -> RT 002 RW 004 DESA TAMBI KECAMATAN WATUKUMPUL KABUPATEN PEMALANG
B39: 3. | C39: Nama Ibu kandung | F39: : | G39: ='ISIAN DATA'!G52 -> KHOSINGAH | J39: NIK : | K39: ='ISIAN DATA'!G53 -> 3327044107810112
C40: Tempat, tanggal lahir | F40: : | G40: ='ISIAN DATA'!G54 -> PEMALANG 01 JULI 1981 | J40: Pekerjaan : | K40: ='ISIAN DATA'!G55 -> Mengurus Rumah Tangga
C41: Tempat tinggal | F41: : | G41: ='ISIAN DATA'!G56 -> RT 002 RW 004 DESA TAMBI KECAMATAN WATUKUMPUL KABUPATEN PEMALANG
A43: D. | C43: CALON WALI NASAB DAN MAS KAWIN (MAHAR)
C44: Nama Wali | F44: : | G44: ='ISIAN DATA'!G58 -> RUSMAN | J44: Bin : | K44: ='ISIAN DATA'!G59 -> MARTA
C45: Tempat, Tanggal Lahir | F45: : | G45: ='ISIAN DATA'!G61 -> PEMALANG, 01 JULI 1974 | J45: NIK : | K45: ='ISIAN DATA'!G60 -> 3327040107740063
C46: Hubungan | F46: : | G46: ='ISIAN DATA'!G64 -> AYAH KANDUNG | J46: Pekerjaan : | K46: ='ISIAN DATA'!G62 -> PETANI/ PEKEBUN
C47: Tempat tinggal | F47: : | G47: ='ISIAN DATA'!G63 -> RT 002 RW 004 DESA TAMBI KECAMATAN WATUKUMPUL KABUPATEN PEMALANG
...

Sheet Kendali Pelaksanaan Ijab
L1: =HYPERLINK("#'Isian Data'!A1", "⬅️ Kembali ke Isisan Data") -> ⬅️ Kembali ke Isisan Data
A2: LEMBAR KENDALI IJAB QABUL
A4: Tempat | B4: : | C4: ='ISIAN DATA'!G6 -> DI RUMAH MEMPELAI PUTRI RT 010 RW 002 DESA TAMBI WATUKUMPUL PEMALANG
A5: Tanggal | B5: : | C5: ='ISIAN DATA'!G4 -> 2026-09-23
A7: Nama Calon Pengantin Pria | E7: : | F7: ='ISIAN DATA'!G8 -> SAEFULOH
B8: Bin | E8: : | F8: ='ISIAN DATA'!G9 -> KUNENI
A10: Nama Calon Pengantin Wanita | E10: : | F10: ='ISIAN DATA'!G34 -> SUSILAH
B11: Binti | E11: : | F11: ='ISIAN DATA'!G35 -> RUSMAN
A13: Wali | B13: (Kedudukan wali) | E13: : | F13: ='ISIAN DATA'!G64 -> AYAH KANDUNG
C14: Nama Wali | E14: : | F14: ='ISIAN DATA'!G58 -> RUSMAN
A16: Mas kawin/ Mahar | E16: : | F16: UANG / ALAT SHALAT/ PERHIASAN EMAS / LOGAM MULIA
F17: RP . | G17: ='ISIAN DATA'!G65 -> 0 | H17: / | I17: ='ISIAN DATA'!J65 -> 0 | J17: Gram
A19: SAKSI PERTAMA
A20: Nama | E20: : | F20: ='ISIAN DATA'!G70 -> JURI
A21: Tempat, tanggal lahir | E21: : | F21: ='ISIAN DATA'!G71 -> PEMALANG, 04 MEI 1966
A22: NIK | E22: : | F22: ='ISIAN DATA'!G72 -> 3327040405660002
A23: Pekerjaan | E23: : | F23: ='ISIAN DATA'!G73 -> KEPALA DESA
A24: Alamat | E24: : | F24: ='ISIAN DATA'!G74 -> RT 010 RW 002 DESA TAMBI KECAMATAN WATUKUMPUL KABUPATEN PEMALANG
A26: Saksi Kedua
A27: Nama | E27: : | F27: ='ISIAN DATA'!G76 -> GHOFUR
A28: Tempat, tanggal lahir | E28: : | F28: ='ISIAN DATA'!G77 -> PURBALINGGA, 10 FEBRUARI 1988
A29: NIK | E29: : | F29: ='ISIAN DATA'!G78 -> 3303171002880003
A30: Pekerjaan | E30: : | F30: ='ISIAN DATA'!G79 -> WIRASWASTA
A31: Alamat | E31: : | F31: ='ISIAN DATA'!G80 -> RT 001 RW 001 DESA JINGKANG KECAMATAN KARANGJAMBU KABUPATEN PURBALINGGA
A35: Catatan lain | E35: : | F35: …....................................................................................

Sheet Pernyataan Wali Hakim
M1: =HYPERLINK("#'Isian Data'!A1", "⬅️ Kembali ke Isisan Data") -> ⬅️ Kembali ke Isisan Data
A2: SURAT PERNYATAAN WALI HAKIM
A4: Assalamu'alaikum Warahmatullahi Wabarakatuh
A5: Yang bertanda tangan dibawah ini, calon pengantin dari | G5: RT 001 RW 001 Tambi Watukumpul
A6: Pemalang, menyatakan dengan sebenar-benarnya, bahwa saya :
B7: Nama | E7: : | F7: ='ISIAN DATA'!G34 -> SUSILAH
B8: Binti | E8: : | F8: ='ISIAN DATA'!G35 -> RUSMAN
B9: Tempat, tanggal lahir | E9: : | F9: ='ISIAN DATA'!G36 -> PEMALANG, 11 SEPTEMBER 1999
B10: NIK | E10: : | F10: ='ISIAN DATA'!G37 -> 3327045109990007
B11: Kewarganegaraan / Agama | E11: :
B12: Pekerjaan | E12: : | F12: ='ISIAN DATA'!G38 -> BELUM/ TIDAK BEKERJA
B13: Alamat | E13: : | F13: ='ISIAN DATA'!G41 -> RT 002 RW 004 DESA TAMBI KECAMATAN WATUKUMPUL KABUPATEN PEMALANG
A16: Menyatakan dengan sebenar-benarnya bahwa ayah saya yang bernama | J16: ='ISIAN DATA'!G45 -> RUSMAN
A17: , sampai hari ini tidak diketahui keberadaannya.
A19: Oleh karena itu kami mohon kepada Bapak Kepala KUA Kecamatan Watukumpul Kabupaten Pemalang,
A20: untuk menjadi wali hakim pernikahan saya dengan calon suami saya yang bernama Mukim bin Kasmah
A21: Yang akan dilaksanakan pada :
B22: Hari/ tanggal | E22: : | F22: 29 Mei 2026
B23: Jam | E23: : | F23: 08.00 WIB
B24: Tempat | E24: : | F24: =F13 -> RT 002 RW 004 DESA TAMBI KECAMATAN WATUKUMPUL KABUPATEN PEMALANG
A26: Demikian surat ini saya buat dengan sebenar-benarnya, dan bisa menjadi landasan hkum ketika terdapat
A27: permasalahan dikemudian hari.
A29: Atas perhatiannya saya ucapkan terima kasih.
A30: Wassalamualaikum, Wr. Wb
I32: ='N4 PEREMPUAN'!I36 -> TAMBI | K32: ='N1 LAKI-LAKI'!I47 -> , TAMBI, 29 JULI 2026
A33: Yang Bertanda Tangan.
A37: =F7 -> SUSILAH
B39: Saksi I | J39: Saksi II
B43: ='ISIAN DATA'!G76 -> GHOFUR | J43: ='ISIAN DATA'!G70 -> JURI
A45: Mengetahui,
A46: Kepala Desa Tambi
A51: JURI

Sheet Surat Keterangan Wali
O1: =HYPERLINK("#'Isian Data'!A1", "⬅️ Kembali ke Isisan Data") -> ⬅️ Kembali ke Isisan Data
A5: PEMERINTAH KABUPATEN PEMALANG
A6: KECAMATAN WATUKUMPUL
A7: DESA TAMBI
A9: Nomor Kode Desa : 33.27.04.2011
A11: SURAT KETERANGAN WALI
A12: ='ISIAN DATA'!G2 -> 400.12.3.2/007/ VII/ 2026
A14: Yang bertanda tangan dibawah ini, menerangkan dengan sesungguhnya:
A16: 1 | B16: Nama Calon Suami | E16: : | F16: ='ISIAN DATA'!G8 -> SAEFULOH
B17: NIK | E17: : | F17: ='ISIAN DATA'!G11 -> 3303170704000001
B18: Bin | E18: : | F18: ='ISIAN DATA'!G9 -> KUNENI
B19: Tempat Tanggal Lahir | E19: : | F19: ='ISIAN DATA'!G10 -> PURBALINGGA , 07 APRIL 2000
B20: Kewarganegaraan/Agama | E20: : | F20: Indonesia
B21: Alamat | E21: : | F21: ='ISIAN DATA'!G16 -> RT 004 RW 001 DESA JINGKANG KECAMATAN KARANGJAMBU KABUPATEN PURBALINGGA
A24: 2 | B24: Nama Calon Istri | E24: : | F24: ='ISIAN DATA'!G34 -> SUSILAH
B25: NIK | E25: : | F25: ='ISIAN DATA'!G37 -> 3327045109990007
B26: Binti | E26: : | F26: ='ISIAN DATA'!G35 -> RUSMAN
B27: Tempat Tanggal Lahir | E27: : | F27: ='ISIAN DATA'!G36 -> PEMALANG, 11 SEPTEMBER 1999
B28: Kewarganegaraan/Agama | E28: : | F28: Indonesia
B29: Alamat | E29: : | F29: ='ISIAN DATA'!G41 -> RT 002 RW 004 DESA TAMBI KECAMATAN WATUKUMPUL KABUPATEN PEMALANG
A32: Akan melaksanakan akad nikah pada hari | B32: Akan melaksanakan akad nikah pada hari | H32: ='ISIAN DATA'!G4 -> 2026-09-23 | J32: dengan menggunakan wali :
A34: A. | B34: Nasab
B35: Nama Wali | E35: : | F35: ='ISIAN DATA'!G58 -> RUSMAN
B36: BIN | E36: : | F36: ='ISIAN DATA'!G59 -> MARTA
B37: Tempat Tanggal Lahir | E37: : | F37: ='ISIAN DATA'!G61 -> PEMALANG, 01 JULI 1974
B38: NIK | E38: : | F38: ='ISIAN DATA'!G60 -> 3327040107740063
B39: Kewarganegaraan/Agama | E39: : | F39: Indonesia/Islam
B40: Pekerjaan | E40: : | F40: ='ISIAN DATA'!G62 -> PETANI/ PEKEBUN
B41: Alamat | E41: : | F41: ='ISIAN DATA'!G63 -> RT 002 RW 004 DESA TAMBI KECAMATAN WATUKUMPUL KABUPATEN PEMALANG
B43: Hubungan | E43: : | F43: ='ISIAN DATA'!G64 -> AYAH KANDUNG
B45: 1 | C45: Ayah Kandung | E45: 8 | F45: Paman Kandung | I45: 15 | J45: Paman Ayah Seayah
B46: 2 | C46: Kakek | E46: 9 | F46: Paman Seayah | I46: 16 | J46: Anak Paman Ayah Kandung
B47: 3 | C47: Buyut | E47: 10 | F47: Anak Paman Kandung | I47: 17 | J47: Anak Paman Ayah Seayah
B48: 4 | C48: Saudara Sekandung | E48: 11 | F48: Anak Paman Seayah | I48: 18 | J48: Paman Kakek Kandung
B49: 5 | C49: Saudara Seayah | E49: 12 | F49: Cucu Paman Kandung | I49: 19 | J49: Paman Kakek Seayah
B50: 6 | C50: Anak Saudara Sekandung | E50: 13 | F50: Cucu Paman Seayah | I50: 20 | J50: Anak Paman Kakek Kandung
B51: 7 | C51: Anak Saudara Seayah | E51: 14 | F51: Paman Ayah Kandung | I51: 21 | J51: Anak Paman Kakek Seayah
A53: Demikian Keterangan ini dibuat dengan sebenar-benarnya untuk menjadi maklum dan digunakan sebagaimana mestinya
J56: ='N4 PEREMPUAN'!I36 -> TAMBI | L56: ='N4 PEREMPUAN'!J36 -> , TAMBI, 29 JULI 2026
A57: Kepala Desa Majakerta | I57: ='N1 LAKI-LAKI'!G48 -> Kepala Desa Tambi
...

Sheet Dispensasi
J1: =HYPERLINK("#'Isian Data'!A1", "⬅️ Kembali ke Isisan Data") -> ⬅️ Kembali ke Isisan Data
A4: PEMERINTAH KABUPATEN PEMALANG
A5: KECAMATAN WATUKUMPUL
A6: DESA | E6: TAMBI
A7: Tambi | B7: ='ISIAN DATA'!H3 -> , TAMBI, 29 JULI 2026
A9: Nomor | B9: ='ISIAN DATA'!G2 -> 400.12.3.2/007/ VII/ 2026
A10: Sifat | B10: Penting
A11: Lampiran | B11: 1
A12: Perihal | B12: Permohonan
A14: Berdasarkan Surat Pengantar dari Kepala Desa | E14: Tambi
A15: Nomor | B15: ='ISIAN DATA'!G2 -> 400.12.3.2/007/ VII/ 2026 | D15: Tgl : | E15: ='ISIAN DATA'!H3 -> , TAMBI, 29 JULI 2026 | G15: perihal pada pokok surat,
A16: dengan ini kami meminta Ijin Dispensasi Nikah kepada Bpk.Camat Watukumpul :
A18: Nama | B18: ='ISIAN DATA'!G34 -> SUSILAH
A19: Umur | B19: ='ISIAN DATA'!K36 -> 27
A20: Pekerjaan | B20: ='ISIAN DATA'!G38 -> BELUM/ TIDAK BEKERJA
A21: Alamat | B21: ='ISIAN DATA'!G41 -> RT 002 RW 004 DESA TAMBI KECAMATAN WATUKUMPUL KABUPATEN PEMALANG
A24: Anak dari
A25: Nama Orangtua calon Istri
A26: Ayah | B26: ='ISIAN DATA'!G45 -> RUSMAN
A27: Ibu | B27: ='ISIAN DATA'!G52 -> KHOSINGAH
A29: Akan menikah dengan
A30: Nama | B30: ='ISIAN DATA'!G8 -> SAEFULOH
A31: Umur | B31: ='ISIAN DATA'!K10 -> 26
A32: Pekerjaan | B32: ='ISIAN DATA'!G12 -> KARYAWAN SWASTA
A33: Alamat | B33: ='ISIAN DATA'!G16 -> RT 004 RW 001 DESA JINGKANG KECAMATAN KARANGJAMBU KABUPATEN PURBALINGGA
A35: Anak dari orangtua calon Suami
A36: Ayah | B36: ='ISIAN DATA'!G19 -> KUNENI
A37: Ibu | B37: ='ISIAN DATA'!G26 -> DARYATI
A39: Pernikahan tersebut akan dilaksanakan pada hari | E39: Kamis | G39: 46240
A40: di Desa Tambi | B40: Kecamatan Watukumpul Kabupaten Pemalang
A42: Demikian untuk menjadikan maklum bagi yang berkentingan.
H45: Tanggal Pelaksanaan
H46: Kepala Desa | I46: Tambi
H50: J U R I
A53: * Tembusan :
A54: 1. Sekertariat Desa Tambi

Sheet STATUS CATIN PR
AA1: =HYPERLINK("#'Isian Data'!A1", "⬅️ Kembali ke Isisan Data") -> ⬅️ Kembali ke Isisan Data
A4: PEMERINTAH KABUPATEN PEMALANG
A5: KECAMATAN WATUKUMPUL
A6: DESA TAMBI
A8: Yang bertanda tangan di bawah ini, saya :
A10: Nama | L10: : | M10: ='ISIAN DATA'!G34 -> SUSILAH
A11: Bin | L11: : | M11: ='ISIAN DATA'!G35 -> RUSMAN
A12: Nomor Induk Kependudukan (NIK) | L12: : | M12: ='ISIAN DATA'!G37 -> 3327045109990007
A13: Tempat, Tanggal Lahir | L13: : | M13: ='ISIAN DATA'!G36 -> PEMALANG, 11 SEPTEMBER 1999
A14: Status Perkawinan | L14: : | M14: ='ISIAN DATA'!G39 -> BELUM KAWIN
A15: Kewarganegaraan | L15: : | M15: INDONESIA
A16: Agama | L16: : | M16: ISLAM
A17: Pekerjaan | L17: : | M17: ='ISIAN DATA'!G12 -> KARYAWAN SWASTA | N17: ='ISIAN DATA'!G38 -> BELUM/ TIDAK BEKERJA
A18: Alamat | L18: : | M18: ='ISIAN DATA'!G41 -> RT 002 RW 004 DESA TAMBI KECAMATAN WATUKUMPUL KABUPATEN PEMALANG
A20: Menyatakan dengan sebenar-benarnya, bahwa saya sampai dengan saat ini berstatus JEJAKA / DUDA*) dan benar-benar BELUM PERNAH MENIKAH dengan siapapun dan dimanapun juga menurut Peraturan Perundang-undangan yang berlaku. Pernyataan ini saya buat dalam keadaan sehat jasmani dan rohani atas dasar kesadaran sendiri tanpa ada paksaan dari pihak manapun.
A22: Surat pernyataan ini saya buat untuk melengkapi persyaratan pernikahan saya dengan seorang perempuan :
A24: Nama | L24: : | M24: ='ISIAN DATA'!G8 -> SAEFULOH
A25: Binti | L25: : | M25: ='ISIAN DATA'!G9 -> KUNENI
A26: Nomor Induk Kependudukan (NIK) | L26: : | M26: ='ISIAN DATA'!G11 -> 3303170704000001
A27: Tempat, Tanggal Lahir | L27: : | M27: ='ISIAN DATA'!G10 -> PURBALINGGA , 07 APRIL 2000
A28: Status Perkawinan | L28: : | M28: ='ISIAN DATA'!G13 -> BELUM KAWIN
A29: Kewarganegaraan | L29: : | M29: INDONESIA
A30: Agama | L30: : | M30: ISLAM
A31: Pekerjaan | L31: : | M31: ='ISIAN DATA'!G12 -> KARYAWAN SWASTA
A32: Alamat | L32: : | M32: ='ISIAN DATA'!G16 -> RT 004 RW 001 DESA JINGKANG KECAMATAN KARANGJAMBU KABUPATEN PURBALINGGA
A34: Apabila di kemudian hari pernyataan ini tidak benar, maka saya bersedia dituntut sesuai dengan hukum dan peraturan perundang-undangan yang berlaku.
A36: Demikian surat pernyataan ini saya buat agar dapat dipergunakan sebagaimana mestinya.
S38: ='Surat Keterangan Wali'!J56 -> TAMBI | T38: ='Surat Keterangan Wali'!L56 -> , TAMBI, 29 JULI 2026
B39: Saksi-saksi : | S39: Yang Menyatakan
A41: 1. | C41: ……………………… | H41: (……………………………)
P42: MATERAI 10.000
A44: 2. | C44: ……………………… | H44: (……………………………) | S44: =M10 -> SUSILAH
A58: * Tembusan :
A59: 1. Sekertariat Desa Tambi

Sheet STATUS LAKI-LAKI
AA1: =HYPERLINK("#'Isian Data'!A1", "⬅️ Kembali ke Isisan Data") -> ⬅️ Kembali ke Isisan Data
A4: PEMERINTAH KABUPATEN PEMALANG
A5: KECAMATAN WATUKUMPUL
A6: DESA TAMBI
A8: Yang bertanda tangan di bawah ini, saya :
A10: Nama | L10: : | M10: UNWAN FALAHI
A11: Bin | L11: : | M11: RATAM
A12: Nomor Induk Kependudukan (NIK) | L12: : | M12: 3327042306970003
A13: Tempat, Tanggal Lahir | L13: : | M13: PEMALANG, 08 MARET 1966
A14: Status Perkawinan | L14: : | M14: BELUM KAWIN
A15: Kewarganegaraan | L15: : | M15: INDONESIA
A16: Agama | L16: : | M16: ISLAM
A17: Pekerjaan | L17: : | M17: BURUH HARIAN LEPAS
A18: Alamat | L18: : | M18: RT 002 RW 001 DESA TAMBI KECAMATAN WATUKUMPUL KABUPATEN PEMALANG
A20: Menyatakan dengan sebenar-benarnya, bahwa saya sampai dengan saat ini berstatus JEJAKA / DUDA*) dan benar-benar BELUM PERNAH MENIKAH dengan siapapun dan dimanapun juga menurut Peraturan Perundang-undangan yang berlaku. Pernyataan ini saya buat dalam keadaan sehat jasmani dan rohani atas dasar kesadaran sendiri tanpa ada paksaan dari pihak manapun.
A22: Surat pernyataan ini saya buat untuk melengkapi persyaratan pernikahan saya dengan seorang perempuan :
A24: Nama | L24: : | M24: IKNA SABELA
A25: Binti | L25: : | M25: WARYONO
A26: Nomor Induk Kependudukan (NIK) | L26: : | M26: 3327044510080002
A27: Tempat, Tanggal Lahir | L27: : | M27: PEMALANG, 05 OKTOBER 2008
A28: Status Perkawinan | L28: : | M28: BELUM KAWIN
A29: Kewarganegaraan | L29: : | M29: INDONESIA
A30: Agama | L30: : | M30: ISLAM
A31: Pekerjaan | L31: : | M31: BURUH HARIAN LEPAS | N31: BELUM/ TIDAK BEKERJA
A32: Alamat | L32: : | M32: RT 003 RW 001 DESA TAMBI KECAMATAN WATUKUMPUL KABUPATEN PEMALANG
A34: Apabila di kemudian hari pernyataan ini tidak benar, maka saya bersedia dituntut sesuai dengan hukum dan peraturan perundang-undangan yang berlaku.
A36: Demikian surat pernyataan ini saya buat agar dapat dipergunakan sebagaimana mestinya.
S38: ='Surat Keterangan Wali'!J56 -> TAMBI | T38: ='Surat Keterangan Wali'!L56 -> , TAMBI, 29 JULI 2026
B39: Saksi-saksi : | S39: Yang Menyatakan
A41: 1. | C41: ……………………… | H41: (……………………………)
P42: MATERAI 10.000
A44: 2. | C44: ……………………… | H44: (……………………………) | S44: =M10 -> UNWAN FALAHI
A58: * Tembusan :
A59: 1. Sekertariat Desa Tambi
